import { describe, it, expect, vi } from 'vitest';
import { render, screen } from '@testing-library/react';
import ErrorBoundary from '../ErrorBoundary';

// Component that throws an error
const ThrowError = ({ shouldThrow }: { shouldThrow: boolean }) => {
  if (shouldThrow) {
    throw new Error('Test error');
  }
  return <div>No error</div>;
};

describe('ErrorBoundary', () => {
  it('should render children when there is no error', () => {
    render(
      <ErrorBoundary>
        <ThrowError shouldThrow={false} />
      </ErrorBoundary>
    );

    expect(screen.getByText('No error')).toBeInTheDocument();
  });

  it('should render error UI when there is an error', () => {
    // Suppress console.error for this test
    const consoleSpy = vi.spyOn(console, 'error').mockImplementation(() => {});

    render(
      <ErrorBoundary>
        <ThrowError shouldThrow={true} />
      </ErrorBoundary>
    );

    expect(screen.getByText('Oops! Something went wrong')).toBeInTheDocument();
    expect(screen.getByText('Try Again')).toBeInTheDocument();
    expect(screen.getByText('Go Home')).toBeInTheDocument();

    consoleSpy.mockRestore();
  });

  it('should render custom fallback when provided', () => {
    const consoleSpy = vi.spyOn(console, 'error').mockImplementation(() => {});
    const customFallback = <div>Custom Error Message</div>;

    render(
      <ErrorBoundary fallback={customFallback}>
        <ThrowError shouldThrow={true} />
      </ErrorBoundary>
    );

    expect(screen.getByText('Custom Error Message')).toBeInTheDocument();

    consoleSpy.mockRestore();
  });
});
